1. 예외처리(execption handling)

- 프로그램이 실행 중 어떠한 원인에 의해 오작동 하거나 비정상적으로 종료되는 경우를 프로그램 에러 또는 오류라고 한다.
- 발생시점에 따라 나누어 지는데, 컴파일 시 발생하는 '컴파일 에러(complie-time error)'와 프로그램이 실행 중 발생하는 '런타임 에러(runtime error)'가 있다.
- 자바에서는 실행 시 발생할 수 있는 프로그램 오류를 '에러(error)'와 '예외(exception)'로 구분한다.
- 에러는 메모리 부족이나 스택오버플로우 처럼 발생시 복구할 수 없는 심각한 오류이고, 예외는 발생하더라도 수습될 수 있는 덜 심각한 것이다.
- 예외처리는 프로그램 실행 시 발생할 수 있는 예기치 못한 예외의 발생에 대비한 코드를 작성하는 것이며, 예외의 발생으로 인한 실행 중인 프로그램의 갑작스런 비정상 종료를 막고, 정상적인 실행을 유지하기 위해 한다. 

```
- 에러(error) : 프로그램 코드에 의해 수습될 수 없는 심각한 오류
- 예외(exception) : 프로그램 코드에 의해 수습될 수 있는 다소 미약한 오류
```



2. 예외처리의 정의와 목적

- 예외처리란, 프로그램 실행 시 발생할 수 있는 예기치 못한 예외의 발생에 대비한 코드를 작성하는 것이다.
- 목적은 예외의 발생으로 인한 실행 중인 프로그램의 갑작스런 비정상 종료를 막고, 정상적인 실행상태를 유지할 수 있도록 하는 것이다.



3. 예외처리 구문 try-catch

```java
try{
	//예외가 발생할 가능성이 있는 문장들을 넣는다.
}catch(Exception1 e1){
	//Exception1이 발생할 경우, 이를 처리하기 위한 문장을 넣는다.
}catch(Exception2 e2){
	//Exception2이 발생할 경우, 이를 처리하기 위한 문장을 넣는다.
}catch(ExceptionN eN){
	//... 
}
```

```java
class ExceptionEx{
	public static void main(String args[]){
		try{
			try{}catch(Exception e){}
		}catch(Exception e){
			try{}catch(Exception e){} // 컴파일 에러
		}
		
		try{
		
		}catch(Exception e){
		
		}
	}
}
```

- try 블럭 또는 catch블럭에 또다른 try-catch블럭이 포함될 수 있다.
- catch블럭의 괄호 내에 선언된 변수는 catch블럭 내에서만 유효하기 때문에, 위의 모든 catch블럭에 참조변수 'e'하나 만을 사용해도 된다.
- 하지만, catch블럭 내에 또 하나의 try-catch문이 포함된 경우, 같은 이름의 참조변수를 사용해서는 안된다. 각 catch 블럭에 선언된 두 참조변수의 영역이 서로 겹치기 때문에 다른 이름을 사용해서 구별해야 한다.

```java
class ExceptionEx{
	public static void main(String args[]){
		int number = 10;
		int result = 0;
		
		for(int i = 0 ; i < 10; i++){
			try{
				result= number / (int)(Math.random()*10); //0으로 나눌때 에러남
				System.out.println(result);
			}catch(ArithmeticException e){
				System.out.println("0");
			}
		}
	}
}
```



4. try-catch문의 흐름

- 예외가 발생한 경우, 발생하지 않은 경우의 흐름이 달라진다.

```pseudocode
- try블럭 내에서 예외가 발생하는 경우
1. 발생한 예외와 일치하는 catch블럭이 있는지 확인한다.
2. 일치하는 catch블럭을 찾게 되면, 그 블럭의 문장을 수행하고 전체 try-catch문을 빠져나가서 그 다음 문장을 계속해서 수행한다. 만일 일치하는 catch블럭이 없다면 예외는 처리되지 못한다.

- try블럭 내에서 예외가 발생하지 않는 경우
1. catch블럭을 거치지 않고 try-catch문을 빠져나가서 수행을 계속한다.
```



5. 예외 발생시키기

-  throw를 사용해서 고의로 예외를 발생시킬 수 있다.

```pseudocode
1. 연산자 new를 이용하여 발생시키려는 예외 클래스의 객체를 만든다.
Exception e = new Exception("고의로 발생");

2. 키워드 throw를 이용해서 예외를 발생시킨다.
throw e;
```

```java
class ExceptionEx{
	public static void main(String args[]){
		try{
			Exception e = new Exception("고의발생");
			throw e;
			//throw new Exception("고의발생");
		}catch(Exception e){
			System.out.println("error : "+ e.getMessage());
			e.printStackTrace();
		}
		System.out.println("정상종료");
	}
}

error : 고의발생
java.lang.Exception : 고의발생
	at Exception.main(ExceptionEx.java:6)
정상종료
```

- Exception인스턴스를 생성할 때, 생성자에 String를 넣어주면, 이 String이  Exception인스턴스에 메세지로 저장된다. getMessage()를 이용해서 얻을 수 있다.

```java
- e.getMessage() : 에러 이벤트와 함께 들어오는 메세지를 출력한다.
- e.toString() : 에러 이벤트의 toString()을 호출해서 간단한 에러 메세지를 확인한다.
- e.printStackTrace() : 에러 메세지의 발생 근원지를 찾아서 단계별로 에러를 출력한다.
```



6. 예외 클래스의 계층 구조

![exception](/images/exception.jpg)

- 모든 예외의 최고 조상은 Exception클래스이다.
- RuntimeException클래스들은 주로 프로그래머의 실수에 의해 발생될 수 있는 예외들이다.

- 그 외 Exception클래스의 자손 예외들은 외부의 영향으로 발생할 수 있는 것들로서, 프로그램의 사용자들의 동작에 의해 발생하는 경우가 많다. 

```
RuntimeException - 프로그래머의 실수로 발생하는 예외. 예외처리보다 발생하지 않도록해야함.
그 외Exception - 사용자의 실수와 같은 외적인 요인에 의해 발생하는 예외.
```



7. 예외의 발생과 catch블럭

- catch블럭은 괄호와 블럭 두 부분으로 나누어져 있는데, 괄호내에는 처리하고자하는 예외와 같은 타입의 참조변수 하나를 선언해야한다.
- 예외가 발생하면, 발생한 예외에 해당하는 클래스의 인스턴스가 만들어 진다. 
- 첫번째 catch블럭부터 차례로 내려가면서 catch블럭의 괄호 내에 선언된 참조변수의 종류와 생성된 예외클래스의 인스턴스에 instanceof연산자를 이용해서 검사하게 되는데, 검사결과가 true인 catch블럭을 만날 때까지 계속된다.

- 모든 예외는 Exception클래스의 자손이므로, catch블럭의 괄호에 Exception클래스 타입의 참조변수를 선언해 놓으면 어떤 종류의 예외가 발생하더라도 이 catch블럭에 의해서 처리된다.

```java
class ExceptionEx{
	public static void main(String[] args){
		System.out.println(1);
		System.out.println(2);
		
		try{
			System.out.println(3);
			System.out.println(0/0);
			system.out.println(4);
		}catch(Exception e){
			System.out.println(5);
		}
		System.out.println(6);
	}
}

1
2
3
5
6
```

```java
class ExceptionEx{
	public static void main(String args[]){
		System.out.println(1);
		System.out.println(2);
		
		try{
			System.out.println(3);
			System.out.println(0/0);
			System.out.println(4);
		}catch(ArithmeticException ae){
			if(ae instanceof ArithmeticException){
				System.out.println("true");
				System.out.println("ArithmeticException");
			}
		}catch(Exception e){
			System.out.println("Exception");
		}
		System.out.println("6");
	}
}


1
2
3
true
ArithmeticException
6
```

- ArithmeticException이 발생하여, 첫 번째 catch블럭을 찾았기 때문에, 두 번째 catch블럭은 검사하지 않는다.

```pseudocode
printStackTrace() : 예외발생 당시의 호출스택(Call Stack)에 있었던 메서드의 정보와 예외 메세지를 화면에 출력한다.

getMessage() : 발생한 예외클래스의 인스턴스에 저장된 메세지를 얻을 수 있다.
```



8. finally 블럭

-  try-catch문과 함께 예외의 발생여부에 상관없이 실행되어야 할 코드를 포함한다.

```
try{

}catch(Exception e){

}finally{
	//예외의 발생여부와 상관없이 항상 수행되어야하는 문장
}
```

```java
class FinallyTest{
	public static void main(String[] args){
		FinallyTest.method();
		System.out.println("END");
	}
	
	static void method(){
		try{
			System.out.pritln("method() 호출");
			return;
		}catch(Exception e){
			e.printStackTrace();
		}finally{
			System.out.pritln("finally");
		}
	}
}

method() 호출
finally
END
```

- return문을 만나더라도 finally블럭의 문장이 먼저 실행 된 후에, 현재 실행 중인 메서드를 종료한다.



9. throws - 메서드 예외 선언하기

- throws 키워드를 사용해서 메서드 내에서 발생할 수 있는 예외를 적어주기만 하면 된다. 예외가 여러개일 경우는 쉼표로 구분한다.
- 메서드의 선언부에 예외를 명시하여 이 메서드를 사용하는 쪽에서는 이에 대한 처리를 하도록 강요한다.

```
void method() throws Exception1, Exception2, ... {
	//메서드 구현부
}
```

- 이것은 예외를 처리하는 것이 아니라 예외가 발생할 가능성이 있는 메서드를 호출한 메서드에게 예외를 전달하여 떠맡기는 것이다.
- 예외를 전달받은 메서드가 또다시 자신을 호출한 메서드에게 전달할 수 있으며, 이런식으로 계속 호출스택에 있는 메서드들을 따라 전달되다가 제일 마지막에 있는 main메서드 에서도 예외가 처리되지 않으면, main메서드 마저 종료되어 프로그램 전체가 종료된다.

```java
class ExceptionEx {
	public static void main(String args[]) throws Exception {
		method1();
	}

	static void method1() throws Exception {
		method2();
	}

	static void method2() throws Exception {
		throw new Exception();
	}
}

Exception in thread "main" java.lang.Exception
	at ExceptionEx.method2(ExceptionEx.java:10)
	at ExceptionEx.method1(ExceptionEx.java:7)
	at ExceptionEx.main(ExceptionEx.java:3)
```

```
- 예외가 발생했을 떄, 3개의 메서드가 호출스택에 있었으며,
- 예외가 발생한 곳은 제일 윗줄에 있는 method2()라는 것과
- main 메서드가 method1()을, 그리고 method1()은 method2()를 호출했다는 것을 알 수 있다.
```

- 결국 어느 한 곳에서는 반드시  try-catch문으로 예외처리를해주어야 한다.

```java
class ExceptionEx {
	public static void main(String args[]) {
		try{
			method1();
		}catch(Exception e){
			System.out.println("main에서 예외처리함.");
			e.printStackTrace();
		}
	}

	static void method1() throws Exception {
		throw new Exception();
	}
}

main에서 예외처리함.
java.lang.Exception
	at ExceptionEx.method1(ExceptionEx.java:12)
	at ExceptionEx.main(ExceptionEx.java:4)
```

```
throw와 throws의 차이
둘 다 Exception을 발생시킨다는 것에는 차이가 없다. 
throw는 현재 메서드의 에러를 처리한 후에 상위 메서드에 에러 정보를 줌으로써 상위 메서드에서도 에러 발생일 감지할 수 있다. 즉, 개발자가 Exception을 강제로 발생시켜 메서드 내에서 예외처리를 수행하는 것이다.
throws는 메서드를 호출한 상위 메서드에 이러한 Exception 처리에 대한 책임을 전가시키는 것이다. 
```



10. 예외 되던지기(exception re-throwing)

- 한 메서드에서 발생할 수 있는 예외가 여럿인 경우, 몇 개는 try-catch문을 통해서 메서드 내에서 자체적으로 처리하고, 그 나머지는 선언부에 지정하여 호출한 메서드에서 처리하도록 함으로써, 양쪽에서 나눠서 처리되도록 할 수 있다.
- 또는, 단 하나의 예외에 대해서도 예외가 발생한 메서드와 호출한 메서드, 양쪽에서 처리하도록 할 수 있다.
- 이것은 예외를 처리한 후에 인위적으로 다시 발생시키는 방법을 통해서 가능한데, 이것을 예외 되던지기라고 한다.
- 예외가 발생할 가능성이 있는 메서드에서 try-catch문을 사용해서 예외를 처리해주고 catch문에서 필요한 작업을 행한 후에 throw문을 사용해서 예외를 다시 발생시킨다. 다시 발생한 예외는 이 메서드를 호출한 메서드에게 전달되고 호출한 메서드의 try-catch문에서 예외를 또다시 처리한다.
- 이 방법은 하나의 예외에 대해서 예외가 발생한 메서드와 이를 호출한 메서드 양쪽 모두에서 처리해줘야 할 작업이 있을 때 사용된다.
- 예외가 발생할 메서드에서는 try-catch문을 사용해서 예외처리를 해줌과 동시에 메서드의 선언부에 발생할 예외를 throws에 지정해줘야 한다.

```java
class ExceptionEx{
	public static void main(String args[]){
		try{
			method1();
		}catch(Exception e){
			System.out.println("main에서 예외처리 되었음.");
		}
	}
	
	static void method1() throws Exception{
		try{
			throw new Exception();
		}catch(Exception e){
			System.out.println("method1에서 예외처리 되었음.");
			throw e;	//다시 예외를 발생시킴.
		}
	}
}

method1에서 예외처리 되었음.
main에서 예외처리 되었음.
```



11. 사용자정의 예외 만들기

- 기존의 정의된 예외 클래스 외에 필요에 따라 프로그래머가 새로운 예외 클래스를 정의하여 사용할 수 있다.
- 보통 Exception클래스로부터 상속받는 클래스를 만들지만, 필요에 따라서 알맞은 예외 클래스를 선택할 수 있다.

```java
class MyException extends Exception{
	MyException(String msg){	//문자열을 매개변수로 받는 생성자
		super(msg); //조상인 Exception클래스의 생성자를 호출
	}
}
```

- Exception클래스로부터 상속받아서 MyException클래스를 만들었다. 필요하다면, 멤버변수나 메서드를 추가할 수 있다. Exception클래스는 생성 시에 String값을 받아서 메세지로 저장할 수 있다. 
- 사용자정의 예외 클래스도 메세지를 저장할 수 있으려면, String을 매개변수로 받는 생성자를 추가해주어야한다.

```java
class MyException extends Exception{
	//에러 코드 값을 저장하기 위한 필드를 추가
	private final int ERR_CODE;	//생성자로 초기화
	
	MyException(String msg, int errCode){
		super(msg);
		ERR_CODE = errCode;
	}
	
	MyException(String msg){
		this(msg, 100);
	}
	
	public int getErrCode(){	//에러 코드를 얻을 수 있는 메서드 추가
		return ERR_CODE;		//이 메서드는 주로  getMessage()와 사용될 것이다.
	}
}
```

- MyException이 발생했을 때, catch블럭에서 getMessage()와 getErrCode()를 사용해서 에러코드와 메세지를 모두 얻을 수 있을 것이다.
